sample_market_data.txt
MSGTYPE = QUOTE, SYMBOL = 9101, BEST_ASK_QUOTE_FLAG = 1, BEST_BID_QUOTE_FLAG =1, BEST_ASK = 33200000000, BEST_BID = 33200000000, TIME = 7:00
MSGTYPE = QUOTE, SYMBOL = 9101, BEST_ASK_QUOTE_FLAG = 3, BEST_BID_QUOTE_FLAG =3, BEST_ASK = 40000000000, BEST_BID = 400000000000, TIME = 7:00
MSGTYPE = QUOTE, SYMBOL = 9101, BEST_ASK_QUOTE_FLAG = 1, BEST_BID_QUOTE_FLAG =1, BEST_ASK = 33200000000, BEST_BID = 33200000000, TIME = 7:00
MSGTYPE = QUOTE, SYMBOL = 9101, BEST_ASK_QUOTE_FLAG = 3, BEST_BID_QUOTE_FLAG =3, BEST_ASK = 40000000000, BEST_BID = 400000000000, TIME = 7:00
MSGTYPE = QUOTE, SYMBOL = 9101, BEST_ASK_QUOTE_FLAG = 1, BEST_BID_QUOTE_FLAG =1, BEST_ASK = 33200000000, BEST_BID = 33200000000, TIME = 7:00
MSGTYPE = QUOTE, SYMBOL = 9101, BEST_ASK_QUOTE_FLAG = 3, BEST_BID_QUOTE_FLAG =3, BEST_ASK = 40000000000, BEST_BID = 400000000000, TIME = 7:00
MSGTYPE = QUOTE, SYMBOL = 9101, BEST_ASK_QUOTE_FLAG = 1, BEST_BID_QUOTE_FLAG =1, BEST_ASK = 33200000000, BEST_BID = 33200000000, TIME = 7:00
MSGTYPE = QUOTE, SYMBOL = 9101, BEST_ASK_QUOTE_FLAG = 3, BEST_BID_QUOTE_FLAG =3, BEST_ASK = 40000000000, BEST_BID = 400000000000, TIME = 7:00
MSGTYPE = QUOTE, SYMBOL = 9101, BEST_ASK_QUOTE_FLAG = 1, BEST_BID_QUOTE_FLAG =1, BEST_ASK = 33200000000, BEST_BID = 33200000000, TIME = 7:00
MSGTYPE = QUOTE, SYMBOL = 9101, BEST_ASK_QUOTE_FLAG = 3, BEST_BID_QUOTE_FLAG =3, BEST_ASK = 40000000000, BEST_BID = 400000000000, TIME = 7:00
MSGTYPE = QUOTE, SYMBOL = 9101, BEST_ASK_QUOTE_FLAG = 1, BEST_BID_QUOTE_FLAG =1, BEST_ASK = 33200000000, BEST_BID = 33200000000, TIME = 7:00
MSGTYPE = QUOTE, SYMBOL = 9101, BEST_ASK_QUOTE_FLAG = 3, BEST_BID_QUOTE_FLAG =3, BEST_ASK = 40000000000, BEST_BID = 400000000000, TIME = 7:00
